Workbook

Sheet Languages
A1: Uri | B1: Label
A2: http://publications.europa.eu/resource/authority/language/OUN | B2: !O!ung
A3: http://publications.europa.eu/resource/authority/language/AUE | B3: =/Kx'au//'ein
A4: http://publications.europa.eu/resource/authority/language/AOU | B4: A'ou
A5: http://publications.europa.eu/resource/authority/language/ADS | B5: Adamorobe Sign Language
A6: http://publications.europa.eu/resource/authority/language/ADP | B6: Adap
A7: http://publications.europa.eu/resource/authority/language/WSG | B7: Adilabad Gondi
A8: http://publications.europa.eu/resource/authority/language/DTH | B8: Adithinngithigh
A9: http://publications.europa.eu/resource/authority/language/ADY | B9: Adyghe
A10: http://publications.europa.eu/resource/authority/language/AFG | B10: Afghan Sign Language
A11: http://publications.europa.eu/resource/authority/language/AFR | B11: Afrikaans
A12: http://publications.europa.eu/resource/authority/language/AFA | B12: Afro-Asiatic languages
... A1221: http://publications.europa.eu/resource/authority/language/GKU | B1221: ǂUngkue

Sheet Catalog
A1: Profile | B1: Field | C1: Requirement | D1: Description | E1: Child | F1: Child Requirement | G1: Auto Calculated (Do not change) | H1: Value
A2: STAGE | B2: existing | C2: REQUIRED | D2: If the dataset will be added to an existing catalog, set to true and provide the url. | G2: =IF(H2="","",H2) -> false | H2: false
A3: STAGE | B3: url | C3: REQUIRED* | D3: * Only required if "existing" is "true" URI of the existing catalog which the dataset will be added. | G3: =IF(H3="","",H3)
A4: HealthDCAT-AP | B4: title | C4: REQUIRED | D4: Title of the catalog | G4: =IF(H4="","",H4) -> STAGE Data Catalog | H4: STAGE Data Catalog
A5: HealthDCAT-AP | B5: description | C5: REQUIRED | D5: Description of the catalog | G5: =IF(H5="","",H5) -> FAIRful metadata catalog for the datasets collected in the scope of STAGE project | H5: FAIRful metadata catalog for the datasets collected in the scope of STAGE project
A6: HealthDCAT-AP | B6: applicableLegislation | C6: REQUIRED | D6: The legislation that mandates the creation or management of the catalog. See: https://eur-lex.europa.eu/eli/reg/ | G6: =IF(H6="","",H6) -> https://eur-lex.europa.eu/eli/reg/2025/327/oj | H6: https://eur-lex.europa.eu/eli/reg/2025/327/oj
H7: STAGE | A7: DCAT-AP | B7: creator | C7: OPTIONAL | D7: An entity responsible for the creation of the catalogue. | E7: name | F7: REQUIRED - Organization ID | G7: =IF(H7="","",H7) -> STAGE
E8: type | F8: FROM Organizations sheet | G8: =_xlfn.IFNA(INDEX(Corporate_Bodies[Uri], MATCH(H8, Corporate_Bodies[Label], 0)),"")
A9: STAGE | B9: geographical coverage | C9: RECOMMENDED | D9: A geographical area covered by the Catalogue. | G9: =IF(Helpers!A2="","",Helpers!A2) -> http://publications.europa.eu/resource/authority/country/FIN,http://publications.europa.eu/resource/authority/country/DNK,http://publications.europa.eu/resource/authority/country/DEU | H9: Finland | I9: Denmark | J9: Germany
A10: STAGE | B10: temporal coverage | C10: RECOMMENDED | D10: A temporal period that the Catalogue covers. | E10: start date | G10: =IF(H10="","",H10) -> 31413 | H10: 31413
E11: end date | G11: =IF(H11="","",H11) -> 46023 | H11: 46023
A12: DCAT-AP | B12: licence | C12: OPTIONAL | D12: A licence under which the Catalogue can be used or reused. | G12: =IF(H12="","",H12) -> http://creativecommons.org/licenses/by/4.0/ | H12: http://creativecommons.org/licenses/by/4.0/
A13: STAGE | B13: themes | C13: FIXED | D13: A knowledge organization system used to classify the Resources that are in the Catalogue. | G13: =IF(H13="","",H13) -> http://publications.europa.eu/resource/authority/data-theme/HEAL | H13: http://publications.europa.eu/resource/authority/data-theme/HEAL
A14: DCAT-AP | B14: homepage | C14: OPTIONAL | D14: A web page that acts as the main page for the Catalogue. | G14: =IF(H14="","",H14) -> https://stage-healthyaging.eu | H14: https://stage-healthyaging.eu
A15: DCAT-AP | B15: language | C15: OPTIONAL | D15: A language used in the textual metadata describing titles, descriptions, etc. of the Datasets in the Catalogue. | G15: =_xlfn.IFNA(INDEX(Languages[Uri], MATCH(H15, Languages[Label], 0)),"") -> http://publications.europa.eu/resource/authority/language/ENG | H15: English
A16: DCAT-AP | B16: modification date | C16: OPTIONAL | D16: The most recent date on which the Catalogue was modified. | G16: =IF(H16="","",H16) -> 45940 | H16: 45940
H17: STAGE | A17: HealthDCAT-AP | B17: publisher | C17: OPTIONAL | D17: * At least one of the contact page and contact email is required - Trusted Data Holder indicates whether the Publisher is recognized as a trusted data holder under relevant health data governance frameworks. An entity (organisation) responsible for making the Catalogue available. | E17: name | F17: REQUIRED - Organization ID | G17: STAGE
E18: contact page | F18: FROM Organizations sheet | G18: =IF(H18="","",H18) -> https://stage-healthyageing.eu/contact
E19: contact email | F19: FROM Organizations sheet | G19: =IF(H19="","",H19) -> sylvain.sebert@oulu.fi
E20: type | F20: FROM Organizations sheet | G20: =IF(H20="","",H20)
E21: description (publisher note) | F21: FROM Organizations sheet | G21: =IF(H21="","",H21) -> The catalog is maintained and published by the STAGE consortium
E22: trusted data holder | F22: FROM Organizations sheet | G22: =IF(H22="","",H22) -> true
A23: DCAT-AP | B23: release date | C23: OPTIONAL | D23: The date of formal issuance (e.g., publication) of the Catalogue. | G23: =IF(H23="","",H23) -> 46023 | H23: 46023
A24: DCAT-AP | B24: rights | C24: OPTIONAL | D24: A statement that specifies rights associated with the Catalogue. | G24: =IF(H24="","",H24) -> This catalog provides descriptive metadata only. Reuse of metadata is permitted with attribution. Access to and reuse of the referenced health datasets may require authorization and is governed by applicable health data protection, ethical approval, and national legislation. | H24: This catalog provides descriptive metadata only. Reuse of metadata is permitted with attribution. Access to and reuse of the referenced health datasets may require authorization and is governed by applicable health data protection, ethical approval, and national legislation.
A25: STAGE | B25: record | C25: EXCLUDED | D25: A Catalogue Record that is part of the Catalogue. | G25: =IF(H25="","",H25)
A26: STAGE | B26: service | C26: EXCLUDED | D26: A site or end-point (Data Service) that is listed in the Catalogue. | G26: =IF(H26="","",H26)
A27: STAGE | B27: catalogue | C27: EXCLUDED | D27: A catalogue whose contents are of interest in the context of this catalogue.
A28: STAGE | B28: has part | C28: EXCLUDED | D28: A related Catalogue that is part of the described Catalogue.

Sheet Access Rights
A1: Label | B1: Uri
A2: PUBLIC | B2: http://publications.europa.eu/resource/authority/access-right/PUBLIC
A3: RESTRICTED | B3: http://publications.europa.eu/resource/authority/access-right/RESTRICTED
A4: NON PUBLIC | B4: http://publications.europa.eu/resource/authority/access-right/NON_PUBLIC

Sheet Frequency
A1: Uri | B1: Label
A2: http://publications.europa.eu/resource/authority/frequency/OP_DATPRO | B2: Provisional data
A3: http://publications.europa.eu/resource/authority/frequency/ANNUAL | B3: annual
A4: http://publications.europa.eu/resource/authority/frequency/AS_NEEDED | B4: as needed
A5: http://publications.europa.eu/resource/authority/frequency/BIDECENNIAL | B5: bidecennial
A6: http://publications.europa.eu/resource/authority/frequency/BIENNIAL | B6: biennial
A7: http://publications.europa.eu/resource/authority/frequency/BIHOURLY | B7: bihourly
A8: http://publications.europa.eu/resource/authority/frequency/BIMONTHLY | B8: bimonthly
A9: http://publications.europa.eu/resource/authority/frequency/BIWEEKLY | B9: biweekly
A10: http://publications.europa.eu/resource/authority/frequency/CONT | B10: continuous
A11: http://publications.europa.eu/resource/authority/frequency/UPDATE_CONT | B11: continuously updated
A12: http://publications.europa.eu/resource/authority/frequency/DAILY | B12: daily
... A42: http://publications.europa.eu/resource/authority/frequency/WEEKLY | B42: weekly

Sheet Media Type
A1: Uri | B1: Label
A2: http://publications.europa.eu/resource/authority/file-type/7Z | B2: 7z
A3: http://publications.europa.eu/resource/authority/file-type/AAB | B3: AAB
A4: http://publications.europa.eu/resource/authority/file-type/AAC | B4: AAC
A5: http://publications.europa.eu/resource/authority/file-type/AKN4EU_LEG | B5: AKN4EU LEG
A6: http://publications.europa.eu/resource/authority/file-type/AKN4EU_ZIP | B6: AKN4EU ZIP
A7: http://publications.europa.eu/resource/authority/file-type/AKN4EU | B7: AKN4EU file
A8: http://publications.europa.eu/resource/authority/file-type/APK | B8: APK
A9: http://publications.europa.eu/resource/authority/file-type/ARC | B9: ARC
A10: http://publications.europa.eu/resource/authority/file-type/ARC_GZ | B10: ARC GZ
A11: http://publications.europa.eu/resource/authority/file-type/ARJ | B11: ARJ
A12: http://publications.europa.eu/resource/authority/file-type/AZW | B12: Amazon Kindle eBook
... A226: http://publications.europa.eu/resource/authority/file-type/XZ | B226: xz

Sheet CI_RoleCode
A1: Code | B1: Description
A2: resourceProvider | B2: party that supplies the resource
A3: custodian | B3: party that accepts accountability and responsibility for the resource and ensures appropriate care and maintenance of the resource
A4: owner | B4: party that owns the resource
A5: user | B5: party who uses the resource
A6: distributor | B6: party who distributes the resource
A7: originator | B7: party who created the resource
A8: pointOfContact | B8: party who can be contacted for acquiring knowledge about or acquisition of the resource
A9: principalInvestigator | B9: key party responsible for gathering information and conducting research
A10: processor | B10: party who has processed the data in a manner such that the resource has been modified
A11: publisher | B11: party who published the resource
A12: author | B12: party who authored the resource
... A21: stakeholder | B21: party who has an interest in the resource or the use of the resource

Sheet Health Activities
A1: Uri | B1: Label
A2: https://hdeu-dcat.acceptance.data.health.europa.eu/resource/authority/health-activity/ADMISSION_DISCHARGE | B2: Admission Discharge
A3: https://hdeu-dcat.acceptance.data.health.europa.eu/resource/authority/health-activity/HOSPITAL_RECORDS | B3: Hospital Records
A4: https://hdeu-dcat.acceptance.data.health.europa.eu/resource/authority/health-activity/HEALTHCARE_VISIT | B4: Healthcare Visit
A5: https://hdeu-dcat.acceptance.data.health.europa.eu/resource/authority/health-activity/OBSERVATIONAL_DATA | B5: Observational Data
A6: https://hdeu-dcat.acceptance.data.health.europa.eu/resource/authority/health-activity/HEALTH_SURVEY | B6: Health Survey
A7: https://hdeu-dcat.acceptance.data.health.europa.eu/resource/authority/health-activity/SURVEILLANCE | B7: Surveillance
A8: https://hdeu-dcat.acceptance.data.health.europa.eu/resource/authority/health-activity/NONMEDICAL_APPLICATION | B8: Nonmedical Application
A9: https://hdeu-dcat.acceptance.data.health.europa.eu/resource/authority/health-activity/SAMPLE_COLLECTIONS | B9: Sample Collections
A10: https://hdeu-dcat.acceptance.data.health.europa.eu/resource/authority/health-activity/QUALITY_REGISTRIES | B10: Quality Registries
A11: https://hdeu-dcat.acceptance.data.health.europa.eu/resource/authority/health-activity/EHEALTH_APPLICATION | B11: Ehealth Application
A12: https://hdeu-dcat.acceptance.data.health.europa.eu/resource/authority/health-activity/ROUTINE_RECORDS | B12: Routine Records
... A35: https://hdeu-dcat.acceptance.data.health.europa.eu/resource/authority/health-activity/INSURANCE_CLAIMS | B35: Insurance Claims

Sheet Dataset
A1: Profile | B1: Field | C1: Requirement | D1: Description | E1: Child | F1: Child Requirement | G1: Auto Calculated (Do not change) | H1: Value | I1: More Values…
A2: DCAT-AP | B2: title | C2: REQUIRED | D2: Title of the dataset | E2: - | F2: - | G2: =H2 -> Core | H2: Core
A3: DCAT-AP | B3: description | C3: REQUIRED | D3: Description of the dataset | E3: - | F3: - | G3: =H3 -> NFBC1986 is a longitudinal one-year birth cohort study from an unselected population. The cohort included all the mothers (N=9362) with children whose expected date of birth felt between July 1st 1985 - June 30th 1986 in the two northernmost provinces on Finland (Oulu and Lapland). | H3: NFBC1986 is a longitudinal one-year birth cohort study from an unselected population. The cohort included all the mothers (N=9362) with children whose expected date of birth felt between July 1st 1985 - June 30th 1986 in the two northernmost provinces on Finland (Oulu and Lapland).
A4: DCAT-AP | B4: identifier | C4: REQUIRED | D4: Identifier URI of the dataset | E4: - | F4: - | G4: =H4 -> http://oulu.fi/NFBC1986/core | H4: http://oulu.fi/NFBC1986/core
A5: STAGE | B5: version | C5: RECOMMENDED | D5: Version of the dataset | E5: - | F5: - | G5: =IF(H5="","",H5) -> 1.0.0 | H5: 1.0.0
A6: STAGE | B6: populationCoverage | C6: RECOMMENDED | D6: A definition of the population within the dataset | E6: - | F6: - | G6: =H6 -> Prenatal, Infant (0-23 months), Child (2-12 years), Adolescent (13-17 years), Young adult (18-24 years), Adult (25-44 years) | H6: Prenatal, Infant (0-23 months), Child (2-12 years), Adolescent (13-17 years), Young adult (18-24 years), Adult (25-44 years)
A7: STAGE | B7: theme | C7: FIXED | D7: Theme of the dataset. In the Health Data Catalogue, all datasets will use the theme 'HEAL' (http://publications.europa.eu/resource/authority/data-theme/HEAL), but additional values from the same vocabulary are allowed. | E7: - | F7: - | G7: http://publications.europa.eu/resource/authority/data-theme/HEAL | H7: HEALTH
A8: HEALTHDCAT-AP | B8: provenance | C8: REQUIRED | D8: Information about how the data was collected, including methodologies, tools, and protocols used | E8: - | F8: - | G8: =H8 -> The original data have been supplemented by data collected with postal questionnaires at the ages of 7, 8 and 16 years and various hospital records and statistical register data. The latest data collection with clinical examinations and questionnaires was at the age of 33 years. | H8: The original data have been supplemented by data collected with postal questionnaires at the ages of 7, 8 and 16 years and various hospital records and statistical register data. The latest data collection with clinical examinations and questionnaires was at the age of 33 years.
A9: HEALTHDCAT-AP | B9: contact point | C9: REQUIRED | D9: *At least one of the page or email is required Contact information that can be used for sending comments about the Dataset. | E9: page | F9: REQUIRED* | G9: =IF(H9="","",H9) -> https://example.com | H9: https://example.com
E10: email | F10: REQUIRED* | G10: =IF(H10="","",H10) -> john.doe@oulu.fi | H10: john.doe@oulu.fi
H11: OULU | A11: HEALTHDCAT-AP | B11: health data access body | C11: REQUIRED | D11: * At least one of the contact page or email is required Health Data Access Body supporting access to data in the Member State. | E11: name | F11: REQUIRED - Organization ID | G11: =H11 -> OULU
E12: type | F12: FROM Organizations sheet | G12: =_xlfn.IFNA(INDEX(Corporate_Bodies[Uri], MATCH(H12, Corporate_Bodies[Label], 0)),"") -> http://publications.europa.eu/resource/authority/corporate-body/EUI
E13: contact point page | F13: FROM Organizations sheet | G13: =IF(H13="","",H13) -> https://oulu.fi
E14: contact point email | F14: FROM Organizations sheet | G14: =IF(H14="","",H14) -> info@oulu.edu.fi
H15: OULU | A15: STAGE | B15: publisher | C15: RECOMMENDED | D15: * At least one of contact page or email is required - Trusted Data Holder indicates whether the Publisher is recognized as a trusted data holder under relevant health data governance frameworks. An entity (organisation) responsible for making the Dataset available. | E15: name | F15: REQUIRED - Organization ID | G15: =IF(H15="","",H15) -> OULU
E16: contact page | F16: FROM Organizations sheet | G16: =IF(H16="","",H16) -> https://oulu.fi
E17: contact email | F17: FROM Organizations sheet | G17: =IF(H17="","",H17) -> info@oulu.edu.fi
E18: type | F18: FROM Organizations sheet | G18: =_xlfn.IFNA(INDEX(Corporate_Bodies[Uri], MATCH(H18, Corporate_Bodies[Label], 0)),"") -> http://publications.europa.eu/resource/authority/corporate-body/EUI
E19: publisher note | F19: FROM Organizations sheet | G19: =IF(H19="","",H19) -> The publisher provides this dataset metadata without warranties of any kind. The publisher shall not be liable for any use of the data beyond the conditions defined by the applicable access and reuse policies.
E20: trusted data holder | F20: FROM Organizations sheet | G20: =IF(H20="","",H20) -> true
A21: HEALTHDCAT-AP | B21: keyword | C21: REQUIRED | D21: Keywords to search the dataset | E21: - | F21: - | G21: =_xlfn.TEXTJOIN(",", TRUE,H21:ZZ21) -> finland,lapland,birth cohort,prenatal,infant,child,adolescent,young adult,adult | H21: finland | I21: lapland | J21: birth cohort | K21: prenatal | L21: infant | M21: child | N21: adolescent | O21: young adult | P21: adult
A22: STAGE | B22: geographical coverage | C22: RECOMMENDED | D22: A geographic region that is covered by the Dataset. Should be provided as URI, see the country URIs in the Value Sets tab. | E22: - | F22: - | G22: =INDEX(Countries[Uri], MATCH(H22, Countries[Label], 0)) -> http://publications.europa.eu/resource/authority/country/FIN | H22: Finland
A23: HEALTHDCAT-AP | B23: healthCategory | C23: REQUIRED | D23: The health category to which this dataset belongs as described in the Commission Regulation on the European Health Data Space laying down a list of categories of electronic data for secondary use, Art.51. See the health categories in the Value Sets tab. | E23: - | F23: - | G23: =INDEX(Health_Categories[Uri], MATCH(H23, Health_Categories[Label], 0)) -> https://hdeu-dcat.acceptance.data.health.europa.eu/resource/authority/healthcategories/EHRS | H23: Electronic Health Data from EHRs
A24: HEALTHDCAT-AP | B24: type | C24: REQUIRED | D24: A type of the Dataset. See the available Dataset Type URIs in the Value Sets tab. | E24: - | F24: - | G24: =INDEX(Dataset_Types[Uri], MATCH(H24, Dataset_Types[Label], 0)) -> http://publications.europa.eu/resource/authority/dataset-type/RELEASE | H24: Release
A25: HEALTHDCAT-AP | B25: applicableLegislation | C25: REQUIRED | D25: The legislation that mandates the creation or management of the dataset. See: https://eur-lex.europa.eu/eli/reg/ | E25: - | F25: - | G25: =IF(H25="","",H25) -> https://eur-lex.europa.eu/eli/reg/2025/327/oj | H25: https://eur-lex.europa.eu/eli/reg/2025/327/oj
A26: HEALTHDCAT-AP | B26: accessRights | C26: REQUIRED | D26: Access rights of the dataset: PUBLIC, NON_PUBLIC or RESTRICTED | E26: - | F26: - | G26: =INDEX(Access_Rights[Uri], MATCH(H26, Access_Rights[Label], 0)) -> http://publications.europa.eu/resource/authority/access-right/PUBLIC | H26: PUBLIC
A27: STAGE | B27: healthTheme | C27: RECOMMENDED | D27: A category of the Dataset or tag describing the Dataset. See the health themes in the Value Sets tab. | E27: - | F27: - | G27: =INDEX(Health_Themes[Uri], MATCH(H27, Health_Themes[Label], 0)) -> https://hdeu-dcat.acceptance.data.health.europa.eu/resource/authority/health-theme/LIFECOURSE_HEALTH | H27: Life-course health: maternal, newborn, child, adolescent ageing
A28: HEALTHDCAT-AP | B28: conforms to | C28: OPTIONAL | D28: An established standard to which the described resource conforms. | E28: - | F28: - | G28: =_xlfn.TEXTJOIN(",", TRUE, H28:AA28) -> https://www.wikidata.org/entity/Q19597236 | H28: https://www.wikidata.org/entity/Q19597236
H29: JOHN_DOE | A29: DCAT-AP | B29: creator | C29: OPTIONAL | D29: An entity responsible for producing the dataset. | E29: name | F29: REQUIRED - Organization ID | G29: =IF(H29="","",H29) -> John Doe
E30: type | F30: FROM Organizations sheet | G30: =IF(H30="","",H30) -> john.doe@oulu.fi
A31: HEALTHDCAT-AP | B31: documentation | C31: OPTIONAL | D31: A page or document about this Dataset. | E31: - | F31: - | G31: =IF(H31="","",H31) -> https://www.oulu.fi/en/university/faculties-and-units/faculty-medicine/northern-finland-birth-cohorts-and-arctic-biobank/nfbc-user-policies | H31: https://www.oulu.fi/en/university/faculties-and-units/faculty-medicine/northern-finland-birth-cohorts-and-arctic-biobank/nfbc-user-policies
A32: STAGE | B32: frequency | C32: RECOMMENDED | D32: The frequency at which the Dataset is updated. | E32: - | F32: - | G32: =_xlfn.IFNA(INDEX(Frequency[Uri], MATCH(H32, Frequency[Label], 0)),"") -> http://publications.europa.eu/resource/authority/frequency/BIMONTHLY | H32: bimonthly
A33: STAGE | B33: sample | C33: RECOMMENDED | D33: A sample distribution of the dataset. | E33: access URL | F33: REQUIRED | G33: =IF(H33="","",H33) -> https://oulu.fi/nfbc1986/sample.csv | H33: https://oulu.fi/nfbc1986/sample.csv
E34: applicableLegislation | F34: REQUIRED | G34: =IF(H34="","",H34) -> http://eur-lex.europa.eu/eli/reg/2025/327/oj | H34: http://eur-lex.europa.eu/eli/reg/2025/327/oj
E35: title | F35: RECOMMENDED | G35: =IF(H35="","",H35) -> NFBC1986 Samples | H35: NFBC1986 Samples
E36: format | F36: RECOMMENDED | G36: =_xlfn.IFNA(INDEX(Media_Type[Uri], MATCH(H36, Media_Type[Label], 0)),"") -> http://publications.europa.eu/resource/authority/file-type/CSV | H36: CSV
A37: STAGE | B37: analytics | C37: OPTIONAL | D37: An analytics distribution of the dataset. | E37: access URL | F37: REQUIRED | G37: =IF(H37="","",H37) -> http://oulu.fi/NFBC1986/analytics.pdf | H37: http://oulu.fi/NFBC1986/analytics.pdf
E38: applicableLegislation | F38: REQUIRED | G38: =IF(H38="","",H38) -> http://eur-lex.europa.eu/eli/reg/2025/327/oj | H38: http://eur-lex.europa.eu/eli/reg/2025/327/oj
E39: title | F39: RECOMMENDED | G39: =IF(H39="","",H39) -> NFBC1986 Dataset Analytics | H39: NFBC1986 Dataset Analytics
E40: format | F40: RECOMMENDED | G40: =_xlfn.IFNA(INDEX(Media_Type[Uri], MATCH(H40, Media_Type[Label], 0)),"") -> http://publications.europa.eu/resource/authority/file-type/PDF | H40: PDF
...

Sheet Helpers
A1: =_xlfn.TEXTJOIN(",", TRUE, H1:AA1) -> https://hdeu-dcat.acceptance.data.health.europa.eu/resource/authority/health-activity/EHEALTH_APPLICATION,https://hdeu-dcat.acceptance.data.health.europa.eu/resource/authority/health-activity/OBSERVATIONAL_DATA,https://hdeu-dcat.acceptance.data.health.europa.eu/resource/authority/health-activity/SURVEILLANCE | H1: =IFERROR(INDEX(Health_Activities[Uri], MATCH(Dataset!H65, Health_Activities[Label], 0)),"") -> https://hdeu-dcat.acceptance.data.health.europa.eu/resource/authority/health-activity/EHEALTH_APPLICATION | I1: =IFERROR(INDEX(Health_Activities[Uri], MATCH(Dataset!I65, Health_Activities[Label], 0)),"") -> https://hdeu-dcat.acceptance.data.health.europa.eu/resource/authority/health-activity/OBSERVATIONAL_DATA | J1: =IFERROR(INDEX(Health_Activities[Uri], MATCH(Dataset!J65, Health_Activities[Label], 0)),"") -> https://hdeu-dcat.acceptance.data.health.europa.eu/resource/authority/health-activity/SURVEILLANCE | K1: =IFERROR(INDEX(Health_Activities[Uri], MATCH(Dataset!K65, Health_Activities[Label], 0)), "") | L1: =IFERROR(INDEX(Health_Activities[Uri], MATCH(Dataset!L65, Health_Activities[Label], 0)), "") | M1: =IFERROR(INDEX(Health_Activities[Uri], MATCH(Dataset!M65, Health_Activities[Label], 0)), "") | N1: =IFERROR(INDEX(Health_Activities[Uri], MATCH(Dataset!N65, Health_Activities[Label], 0)), "") | O1: =IFERROR(INDEX(Health_Activities[Uri], MATCH(Dataset!O65, Health_Activities[Label], 0)), "") | P1: =IFERROR(INDEX(Health_Activities[Uri], MATCH(Dataset!P65, Health_Activities[Label], 0)), "") | Q1: =IFERROR(INDEX(Health_Activities[Uri], MATCH(Dataset!Q65, Health_Activities[Label], 0)), "") | R1: =IFERROR(INDEX(Health_Activities[Uri], MATCH(Dataset!R65, Health_Activities[Label], 0)), "") | ... AA1: =IFERROR(INDEX(Health_Activities[Uri], MATCH(Dataset!AA65, Health_Activities[Label], 0)), "")
A2: =_xlfn.TEXTJOIN(",",TRUE,H2:Z2) -> http://publications.europa.eu/resource/authority/country/FIN,http://publications.europa.eu/resource/authority/country/DNK,http://publications.europa.eu/resource/authority/country/DEU | H2: =IFERROR(INDEX(Countries[Uri], MATCH(Catalog!H9, Countries[Label], 0)),"") -> http://publications.europa.eu/resource/authority/country/FIN | I2: =IFERROR(INDEX(Countries[Uri], MATCH(Catalog!I9, Countries[Label], 0)),"") -> http://publications.europa.eu/resource/authority/country/DNK | J2: =IFERROR(INDEX(Countries[Uri], MATCH(Catalog!J9, Countries[Label], 0)),"") -> http://publications.europa.eu/resource/authority/country/DEU | K2: =IFERROR(INDEX(Countries[Uri], MATCH(Catalog!K9, Countries[Label], 0)),"") | L2: =IFERROR(INDEX(Countries[Uri], MATCH(Catalog!L9, Countries[Label], 0)),"") | M2: =IFERROR(INDEX(Countries[Uri], MATCH(Catalog!M9, Countries[Label], 0)),"") | N2: =IFERROR(INDEX(Countries[Uri], MATCH(Catalog!N9, Countries[Label], 0)),"") | O2: =IFERROR(INDEX(Countries[Uri], MATCH(Catalog!O9, Countries[Label], 0)),"") | ... Z2: =IFERROR(INDEX(Countries[Uri], MATCH(Catalog!Z9, Countries[Label], 0)),"")

Sheet Personal Data
A1: Uri | B1: Label
A2: https://w3id.org/dpv/pd#Accent | B2: Accent
A3: https://w3id.org/dpv/pd#AccountIdentifier | B3: AccountIdentifier
A4: https://w3id.org/dpv/pd#Acquantaince | B4: Acquantaince
A5: https://w3id.org/dpv/pd#Age | B5: Age
A6: https://w3id.org/dpv/pd#AgeExact | B6: AgeExact
A7: https://w3id.org/dpv/pd#AgeRange | B7: AgeRange
A8: https://w3id.org/dpv/pd#ApartmentOwned | B8: ApartmentOwned
A9: https://w3id.org/dpv/pd#Association | B9: Association
A10: https://w3id.org/dpv/pd#Attitude | B10: Attitude
A11: https://w3id.org/dpv/pd#Authenticating | B11: Authenticating
A12: https://w3id.org/dpv/pd#AuthenticationHistory | B12: AuthenticationHistory
... A214: https://w3id.org/dpv/pd#WorkHistory | B214: WorkHistory

Sheet PersonalData
A1: Uri | B1: Label
A2: https://w3id.org/dpv/pd#Accent | B2: Accent
A3: https://w3id.org/dpv/pd#AccountIdentifier | B3: AccountIdentifier
A4: https://w3id.org/dpv/pd#Acquantaince | B4: Acquantaince
A5: https://w3id.org/dpv/pd#Age | B5: Age
A6: https://w3id.org/dpv/pd#AgeExact | B6: AgeExact
A7: https://w3id.org/dpv/pd#AgeRange | B7: AgeRange
A8: https://w3id.org/dpv/pd#ApartmentOwned | B8: ApartmentOwned
A9: https://w3id.org/dpv/pd#Association | B9: Association
A10: https://w3id.org/dpv/pd#Attitude | B10: Attitude
A11: https://w3id.org/dpv/pd#Authenticating | B11: Authenticating
A12: https://w3id.org/dpv/pd#AuthenticationHistory | B12: AuthenticationHistory
... A214: https://w3id.org/dpv/pd#WorkHistory | B214: WorkHistory

Sheet Availabilities
A1: Uri | B1: Label
A2: http://publications.europa.eu/resource/authority/planned-availability/OP_DATPRO | B2: Provisional data
A3: http://publications.europa.eu/resource/authority/planned-availability/AVAILABLE | B3: available
A4: http://publications.europa.eu/resource/authority/planned-availability/EXPERIMENTAL | B4: experimental
A5: http://publications.europa.eu/resource/authority/planned-availability/STABLE | B5: stable
A6: http://publications.europa.eu/resource/authority/planned-availability/TEMPORARY | B6: temporary

Sheet Checksum Algorithms
A1: Uri | B1: Label
A2: https://spdx.org/rdf/terms#checksumAlgorithm_adler32 | B2: adler32
A3: https://spdx.org/rdf/terms#checksumAlgorithm_blake2b256 | B3: blake2b256
A4: https://spdx.org/rdf/terms#checksumAlgorithm_blake2b384 | B4: blake2b384
A5: https://spdx.org/rdf/terms#checksumAlgorithm_blake2b512 | B5: blake2b512
A6: https://spdx.org/rdf/terms#checksumAlgorithm_blake3 | B6: blake3
A7: https://spdx.org/rdf/terms#checksumAlgorithm_md2 | B7: md2
A8: https://spdx.org/rdf/terms#checksumAlgorithm_md4 | B8: md4
A9: https://spdx.org/rdf/terms#checksumAlgorithm_md5 | B9: md5
A10: https://spdx.org/rdf/terms#checksumAlgorithm_md6 | B10: md6
A11: https://spdx.org/rdf/terms#checksumAlgorithm_sha1 | B11: sha1
A12: https://spdx.org/rdf/terms#checksumAlgorithm_sha224 | B12: sha224
... A18: https://spdx.org/rdf/terms#checksumAlgorithm_sha512 | B18: sha512

Sheet Distribution Status
A1: Uri | B1: Label
A2: http://publications.europa.eu/resource/authority/distribution-status/OP_DATPRO | B2: Provisional data
A3: http://publications.europa.eu/resource/authority/distribution-status/COMPLETED | B3: completed
A4: http://publications.europa.eu/resource/authority/distribution-status/DEPRECATED | B4: deprecated
A5: http://publications.europa.eu/resource/authority/distribution-status/DEVELOP | B5: under development
A6: http://publications.europa.eu/resource/authority/distribution-status/WITHDRAWN | B6: withdrawn

Sheet Distribution
A1: Profile | B1: Field | C1: Requirement | D1: Description | E1: Child | F1: Child Requirement | G1: Auto Calculated (Do not change) | H1: Value | I1: More Values…
A2: DCAT-AP | B2: title | C2: OPTIONAL | D2: Title of the distribution | G2: =IF(H2="","",H2) -> Distribution | H2: Distribution
A3: HEALTHDCAT-AP | B3: applicableLegislation | C3: REQUIRED | D3: The legislation that mandates the creation or management of the distribution. See: https://eur-lex.europa.eu/eli/reg/ | G3: =IF(H3="","",H3) -> https://eur-lex.europa.eu/eli/reg/2025/327/oj | H3: https://eur-lex.europa.eu/eli/reg/2025/327/oj
A4: DCAT-AP | B4: accessUrl | C4: REQUIRED | D4: A URL that gives access to a Distribution of the Dataset. | G4: =IF(H4="","",H4) -> https://www.oulu.fi/nfbc | H4: https://www.oulu.fi/nfbc
A5: DCAT-AP | B5: availability | C5: OPTIONAL | D5: An indication how long it is planned to keep the Distribution of the Dataset available. | G5: =_xlfn.IFNA(INDEX(Availabilities[Uri], MATCH(H5, Availabilities[Label], 0)),"") -> http://publications.europa.eu/resource/authority/planned-availability/EXPERIMENTAL | H5: experimental
A6: DCAT-AP | B6: byte size | C6: OPTIONAL | D6: The size of a Distribution in bytes. | G6: =IF(H6="","",H6) -> 500000 | H6: 500000
A7: DCAT-AP | B7: checksum | C7: OPTIONAL | D7: A cryptographic mechanism that can be used to verify that the contents of a distribution have not changed. | E7: algorithm | F7: REQUIRED | G7: =_xlfn.IFNA(INDEX(Checksum_Algorithms[Uri], MATCH(H7, Checksum_Algorithms[Label], 0)),"") -> https://spdx.org/rdf/terms#checksumAlgorithm_md5 | H7: md5
A8: DCAT-AP | E8: value | F8: REQUIRED | G8: =IF(H8="","",H8) -> b931c1fdf1e64022d63859a66cb8f697 a1cce5b9a0d3e656cb4b99b33d58cc51 67f488d5fb430ff3dffded4cc75afb05 728378b77e624da5397ceefb582aced1 a1bbec7ff1db520e7be9523d5abbc086 776d7bcb1565f8b37bac90fcddadf413 46f3ebc2f3c07b9cf736732dc0568d11 411ad2295c88c87e5de60c9f3dd0e93d ba5ebb9d1e7b72f37032417fff42eb12 ecb9beedccc1684966a167d5dedff2f1 | H8: b931c1fdf1e64022d63859a66cb8f697 a1cce5b9a0d3e656cb4b99b33d58cc51 67f488d5fb430ff3dffded4cc75afb05 728378b77e624da5397ceefb582aced1 a1bbec7ff1db520e7be9523d5abbc086 776d7bcb1565f8b37bac90fcddadf413 46f3ebc2f3c07b9cf736732dc0568d11 411ad2295c88c87e5de60c9f3dd0e93d ba5ebb9d1e7b72f37032417fff42eb12 ecb9beedccc1684966a167d5dedff2f1
A9: DCAT-AP | B9: compression format | C9: OPTIONAL | D9: The format of the file in which the data is contained in a compressed form, e.g. to reduce the size of the downloadable file. | G9: =_xlfn.IFNA(INDEX(Media_Type[Uri], MATCH(H9, Media_Type[Label], 0)),"") -> http://publications.europa.eu/resource/authority/file-type/ZIP | H9: ZIP
A10: DCAT-AP | B10: description | C10: OPTIONAL | D10: A free-text account of the Distribution. | G10: =IF(H10="","",H10) -> Example description… | H10: Example description…
A11: DCAT-AP | B11: documentation | C11: OPTIONAL | D11: A page or document about this Distribution. | G11: =IF(H11="","",H11) -> https://example.distribution.com/docs | H11: https://example.distribution.com/docs
A12: DCAT-AP | B12: download URL | C12: OPTIONAL | D12: A URL that is a direct link to a downloadable file in a given format. | G12: =IF(H12="","",H12) -> https://downloadable.distribution.com/example | H12: https://downloadable.distribution.com/example
A13: DCAT-AP | B13: format | C13: OPTIONAL | D13: The file format of the Distribution. | G13: =_xlfn.IFNA(INDEX(Media_Type[Uri], MATCH(H13, Media_Type[Label], 0)),"") -> http://publications.europa.eu/resource/authority/file-type/JSON | H13: JSON
A14: DCAT-AP | B14: has policy | C14: OPTIONAL | D14: NOTE: You can describe the policies as free-text. They will be converted to machine readable ODRL policies manually by STAGE technical partners, if needed. The policy expressing the rights associated with the distribution if using the [ODRL] vocabulary. | E14: Permission | F14: OPTIONAL | G14: =IF(H14="","",H14)
E15: Prohibition | F15: OPTIONAL | G15: =IF(H15="","",H15)
E16: Obligation | F16: OPTIONAL | G16: =IF(H16="","",H16) -> Should be approved by STAGE consortium | H16: Should be approved by STAGE consortium
A17: DCAT-AP | B17: language | C17: OPTIONAL | D17: A language used in the Distribution. | G17: =_xlfn.IFNA(INDEX(Languages[Uri], MATCH(H17, Languages[Label], 0)),"") -> http://publications.europa.eu/resource/authority/language/FIN | H17: Finnish
A18: STAGE | B18: licence | C18: RECOMMENDED | D18: A licence under which the Distribution is made available. | G18: =IF(H18="","",H18) -> http://creativecommons.org/licenses/by/4.0/ | H18: http://creativecommons.org/licenses/by/4.0/
A19: DCAT-AP | B19: linked schemas | C19: OPTIONAL | D19: Reference technical standards, data models, or schema specifications (e.g., HL7 FHIR, OMOP CDM) that define the structure and semantics of this distribution. | G19: =_xlfn.TEXTJOIN(",",TRUE,H19:Z19) -> http://hl7.org/fhir/R4 | H19: http://hl7.org/fhir/R4
A20: DCAT-AP | B20: media type | C20: OPTIONAL | D20: The media type of the Distribution as defined in the official register of media types managed by IANA. Specify the precise IANA media type (e.g., application/json, text/csv, application/fhir+json) to enable proper content handling by consuming applications. | G20: =IF(H20="","",H20) -> application/json+fhir | H20: application/json+fhir
A21: DCAT-AP | B21: modification date | C21: OPTIONAL | D21: The most recent date on which the Distribution was changed or modified. | G21: =H21 -> 45658 | H21: 45658
A22: DCAT-AP | B22: packaging format | C22: OPTIONAL | D22: The format of the file in which one or more data files are grouped together, e.g. to enable a set of related files to be downloaded together. (7z, zip, etc.) | G22: =_xlfn.IFNA(INDEX(Media_Type[Uri], MATCH(H22, Media_Type[Label], 0)),"") -> http://publications.europa.eu/resource/authority/file-type/ZIP | H22: ZIP
A23: DCAT-AP | B23: release date | C23: OPTIONAL | D23: The date of formal issuance (e.g., publication) of the Distribution. | G23: =H23 -> 45658 | H23: 45658
A24: DCAT-AP | B24: rights | C24: OPTIONAL | D24: Detail intellectual property rights, usage restrictions, and access permissions governing this distribution, complementing license information. | G24: =_xlfn.TEXTJOIN(",", TRUE,H24:Z24) -> Reuse of the data is permitted with attribution. Access to and reuse of the referenced health datasets may require authorization and is governed by applicable health data protection, ethical approval, and national legislation. | H24: Reuse of the data is permitted with attribution. Access to and reuse of the referenced health datasets may require authorization and is governed by applicable health data protection, ethical approval, and national legislation.
A25: DCAT-AP | B25: spatial resolution | C25: OPTIONAL | D25: The minimum spatial separation resolvable in a dataset distribution, measured in meters. | G25: =IF(H25="","",H25) -> 5000 | H25: 5000
A26: DCAT-AP | B26: status | C26: OPTIONAL | D26: The status of the distribution in the context of maturity lifecycle. | G26: =_xlfn.IFNA(INDEX(Distribution_Status[Uri], MATCH(H26, Distribution_Status[Label], 0)),"") -> http://publications.europa.eu/resource/authority/distribution-status/COMPLETED | H26: completed
A27: DCAT-AP | B27: temporal resolution | C27: OPTIONAL | D27: FORMAT: P[year,month,day][T[hour,minute,seconds]] EXAMPLE: P1Y (1 year), P15D (15 days), PT1H (1 hour) The minimum time period resolvable in the dataset distribution. | G27: =IF(H27="","",H27) -> P1Y | H27: P1Y
A28: DCAT-AP | B28: access service | C28: OPTIONAL | D28: A data service that gives access to the distribution of the dataset.

Sheet Data Dictionary
A1: Variable | B1: Name | C1: Description | D1: Datatype | E1: Property URL (ontology) | F1: Unit
A2: adhd_raw | B2: Row sums of swan items | C2: Row sums of swan items when all items were answered | D2: integer
A3: age_7y | B3: Child's exact age in years at 7yo follow up study | C3: Child's exact age in years at 7yo follow up study | D3: integer | F3: year
A4: birch_sp | B4: Skin prick results, birch | C4: Skin prick results, birch | D4: binary
A5: C8600Q1_004 | B5: Placental weight | C5: Placental weight | D5: integer | F5: gram
A6: maternal_smoking | B6: Maternal smoking | C6: Maternal smoking during pregnancy | D6: string | E6: http://snomed.info/sct

Sheet Corporate Bodies
A1: Uri | B1: Label
A2: http://publications.europa.eu/resource/authority/corporate-body/ACP_AMB | B2: ACP Committee of Ambassadors
A3: http://publications.europa.eu/resource/authority/corporate-body/ACP_MIN | B3: ACP Council of Ministers
A4: http://publications.europa.eu/resource/authority/corporate-body/CMT_AMB_EC_ACP | B4: ACP–EC Committee of Ambassadors
A5: http://publications.europa.eu/resource/authority/corporate-body/COUN_AMB_EC_ACP | B5: ACP–EC Council of Ministers
A6: http://publications.europa.eu/resource/authority/corporate-body/ACP_EC_JA | B6: ACP–EC Joint Assembly
A7: http://publications.europa.eu/resource/authority/corporate-body/COUN_ASS_ACP_EEC | B7: ACP–EEC Association Council
A8: http://publications.europa.eu/resource/authority/corporate-body/CMT_AMB_EEC_ACP | B8: ACP–EEC Committee of Ambassadors
A9: http://publications.europa.eu/resource/authority/corporate-body/ACP_EEC_CA | B9: ACP–EEC Consultative Assembly
A10: http://publications.europa.eu/resource/authority/corporate-body/COUN_AMB_EEC_ACP | B10: ACP–EEC Council of Ministers
A11: http://publications.europa.eu/resource/authority/corporate-body/CMT_MIX_ACP_EEC | B11: ACP–EEC Joint Committee
A12: http://publications.europa.eu/resource/authority/corporate-body/CMT_AMB_EU_ACP | B12: ACP–EU Committee of Ambassadors
... A1945: http://publications.europa.eu/resource/authority/corporate-body/WP_YOUTH | B1945: Youth Working Party

Sheet Health Themes
A1: Uri | B1: Label
A2: https://hdeu-dcat.acceptance.data.health.europa.eu/resource/authority/health-theme/ENVIRONMENTAL_HEALTH | B2: Environmental, occupational radiation health (incl. WASH urban)
A3: https://hdeu-dcat.acceptance.data.health.europa.eu/resource/authority/health-theme/NUTRITION_SECURITY | B3: Nutrition food security
A4: https://hdeu-dcat.acceptance.data.health.europa.eu/resource/authority/health-theme/TROPICAL_DISEASES | B4: Neglected tropical, parasitic fungal skin diseases
A5: https://hdeu-dcat.acceptance.data.health.europa.eu/resource/authority/health-theme/RESPIRATORY_DISEASES | B5: Respiratory infectious diseases
A6: https://hdeu-dcat.acceptance.data.health.europa.eu/resource/authority/health-theme/VECTOR_DISEASES | B6: Vector-borne zoonotic viral diseases
A7: https://hdeu-dcat.acceptance.data.health.europa.eu/resource/authority/health-theme/EMERGENCY_SETTINGS | B7: Emergencies, disasters, travel humanitarian settings
A8: https://hdeu-dcat.acceptance.data.health.europa.eu/resource/authority/health-theme/REPRODUCTIVE_HEALTH | B8: Sexual reproductive health and rights
A9: https://hdeu-dcat.acceptance.data.health.europa.eu/resource/authority/health-theme/BLOOD_INFECTIONS | B9: Blood-borne sexually transmitted infections
A10: https://hdeu-dcat.acceptance.data.health.europa.eu/resource/authority/health-theme/HEALTH_PRODUCTS | B10: Health products, technologies, data research
A11: https://hdeu-dcat.acceptance.data.health.europa.eu/resource/authority/health-theme/LIFECOURSE_HEALTH | B11: Life-course health: maternal, newborn, child, adolescent ageing
A12: https://hdeu-dcat.acceptance.data.health.europa.eu/resource/authority/health-theme/ENTERIC_INFECTIONS | B12: Enteric, water- food-borne infections
... A21: https://hdeu-dcat.acceptance.data.health.europa.eu/resource/authority/health-theme/CANCER_DISEASE | B21: Cancer

Sheet Health Categories
A1: Uri | B1: Label
A2: https://hdeu-dcat.acceptance.data.health.europa.eu/resource/authority/healthcategories/PGEH | B2: Personal electronic health data automatically generated through medical devices
A3: https://hdeu-dcat.acceptance.data.health.europa.eu/resource/authority/healthcategories/RQSH | B3: Data from research cohorts, questionnaires and surveys related to health, after the first publication of the related results
A4: https://hdeu-dcat.acceptance.data.health.europa.eu/resource/authority/healthcategories/NRPE | B4: Aggregated data on healthcare needs, resources allocated to healthcare, the provision of and access to healthcare, healthcare expenditure and financing
A5: https://hdeu-dcat.acceptance.data.health.europa.eu/resource/authority/healthcategories/RMMD | B5: Data from registries for medicinal products and medical devices
A6: https://hdeu-dcat.acceptance.data.health.europa.eu/resource/authority/healthcategories/DIOH | B6: Data on factors impacting on health, including socio-economic, environmental and behavioural determinants of health
A7: https://hdeu-dcat.acceptance.data.health.europa.eu/resource/authority/healthcategories/EMRD | B7: Other health data from medical devices
A8: https://hdeu-dcat.acceptance.data.health.europa.eu/resource/authority/healthcategories/EHCT | B8: Data from clinical trials, clinical studies, clinical investigations and performance studies subject to Regulation (EU) No 536/2014, Regulation (EU) 2024/1938 of the European Parliament and of the Council34, Regulation (EU) 2017/745 and Regulation (EU) 2017/746
A9: https://hdeu-dcat.acceptance.data.health.europa.eu/resource/authority/healthcategories/EHRS | B9: Electronic Health Data from EHRs
A10: https://hdeu-dcat.acceptance.data.health.europa.eu/resource/authority/healthcategories/MRMR | B10: Data from medical registries and mortality registries
A11: https://hdeu-dcat.acceptance.data.health.europa.eu/resource/authority/healthcategories/HRAD | B11: Healthcare-related administrative data, including on dispensations, reimbursement claims and reimbursements
A12: https://hdeu-dcat.acceptance.data.health.europa.eu/resource/authority/healthcategories/IDHP | B12: Data on professional status, and on the specialisation and institution of health professionals involved in the treatment of a natural person
... A18: https://hdeu-dcat.acceptance.data.health.europa.eu/resource/authority/healthcategories/WELA | B18: Data from wellness applications

Sheet Dataset Types
A1: Uri | B1: Label
A2: http://publications.europa.eu/resource/authority/dataset-type/ATTO_LEX | B2: ATTO table – EUR-Lex domain
A3: http://publications.europa.eu/resource/authority/dataset-type/ATTO_PUB | B3: ATTO table – Publications domain
A4: http://publications.europa.eu/resource/authority/dataset-type/APROF | B4: Application profile
A5: http://publications.europa.eu/resource/authority/dataset-type/CODE_LIST | B5: Code list
A6: http://publications.europa.eu/resource/authority/dataset-type/CORE_COMP | B6: Core component
A7: http://publications.europa.eu/resource/authority/dataset-type/DIRECTORY | B7: Directory
A8: http://publications.europa.eu/resource/authority/dataset-type/DOMAIN_MODEL | B8: Domain model
A9: http://publications.europa.eu/resource/authority/dataset-type/GEOSPATIAL | B9: Geospatial data
A10: http://publications.europa.eu/resource/authority/dataset-type/GLOSSARY | B10: Glossary
A11: http://publications.europa.eu/resource/authority/dataset-type/HVD | B11: High-value dataset
A12: http://publications.europa.eu/resource/authority/dataset-type/IEPD | B12: Information exchange package description
... A26: http://publications.europa.eu/resource/authority/dataset-type/THESAURUS | B26: Thesaurus

Sheet Countries
A1: Uri | B1: Label
A2: http://publications.europa.eu/resource/authority/country/XXU | B2: Abyei region
A3: http://publications.europa.eu/resource/authority/country/AFG | B3: Afghanistan
A4: http://publications.europa.eu/resource/authority/country/XXC | B4: Aksai Chin
A5: http://publications.europa.eu/resource/authority/country/ALB | B5: Albania
A6: http://publications.europa.eu/resource/authority/country/DZA | B6: Algeria
A7: http://publications.europa.eu/resource/authority/country/ASM | B7: American Samoa
A8: http://publications.europa.eu/resource/authority/country/AND | B8: Andorra
A9: http://publications.europa.eu/resource/authority/country/AGO | B9: Angola
A10: http://publications.europa.eu/resource/authority/country/AIA | B10: Anguilla
A11: http://publications.europa.eu/resource/authority/country/ATA | B11: Antarctica
A12: http://publications.europa.eu/resource/authority/country/ATG | B12: Antigua and Barbuda
... A346: http://publications.europa.eu/resource/authority/country/ALA | B346: Åland Islands

Sheet Value Sets
A1: Health Themes | B1: Sütun1
A2: https://hdeu-dcat.acceptance.data.health.europa.eu/resource/authority/health-theme/ENVIRONMENTAL_HEALTH | B2: Environmental, occupational radiation health (incl. WASH urban)
A3: https://hdeu-dcat.acceptance.data.health.europa.eu/resource/authority/health-theme/NUTRITION_SECURITY | B3: Nutrition food security
A4: https://hdeu-dcat.acceptance.data.health.europa.eu/resource/authority/health-theme/TROPICAL_DISEASES | B4: Neglected tropical, parasitic fungal skin diseases
A5: https://hdeu-dcat.acceptance.data.health.europa.eu/resource/authority/health-theme/RESPIRATORY_DISEASES | B5: Respiratory infectious diseases
A6: https://hdeu-dcat.acceptance.data.health.europa.eu/resource/authority/health-theme/VECTOR_DISEASES | B6: Vector-borne zoonotic viral diseases
A7: https://hdeu-dcat.acceptance.data.health.europa.eu/resource/authority/health-theme/EMERGENCY_SETTINGS | B7: Emergencies, disasters, travel humanitarian settings
A8: https://hdeu-dcat.acceptance.data.health.europa.eu/resource/authority/health-theme/REPRODUCTIVE_HEALTH | B8: Sexual reproductive health and rights
A9: https://hdeu-dcat.acceptance.data.health.europa.eu/resource/authority/health-theme/BLOOD_INFECTIONS | B9: Blood-borne sexually transmitted infections
A10: https://hdeu-dcat.acceptance.data.health.europa.eu/resource/authority/health-theme/HEALTH_PRODUCTS | B10: Health products, technologies, data research
A11: https://hdeu-dcat.acceptance.data.health.europa.eu/resource/authority/health-theme/LIFECOURSE_HEALTH | B11: Life-course health: maternal, newborn, child, adolescent ageing
A12: https://hdeu-dcat.acceptance.data.health.europa.eu/resource/authority/health-theme/ENTERIC_INFECTIONS | B12: Enteric, water- food-borne infections
... A416: http://publications.europa.eu/resource/authority/country/ALA | B416: Åland Islands
A418: Corporate Body (Health Data Access Body type)
A419: Since the list is very long, they're not included in this excel. Click the link below to see the table of possible options:
A420: https://publications.europa.eu/webapi/rdf/sparql?default-graph-uri=&query=PREFIX+skos%3A+%3Chttp%3A%2F%2Fwww.w3.org%2F2004%2F02%2Fskos%2Fcore%23%3E%0D%0A%0D%0ASELECT+DISTINCT+%3Furi+%3Flabel+WHERE+%7B%0D%0A++GRAPH+%3Chttp%3A%2F%2Fpublications.europa.eu%2Fresource%2Fauthority%2Fcorporate-body%3E+%7B%0D%0A++++%3Furi+skos%3AinScheme+%3Chttp%3A%2F%2Fpublications.europa.eu%2Fresource%2Fauthority%2Fcorporate-body%3E+%3B%0D%0A+++++++++++++skos%3AprefLabel+%3Flabel+.%0D%0A++%7D%0D%0A++FILTER%28lang%28%3Flabel%29+%3D+%22en%22%29%0D%0A%7D%0D%0AORDER+BY+%3Flabel&format=text%2Fhtml&timeout=0&debug=on&run=+Run+Query+

Sheet Organizations
A1: Organization ID | B1: Name | C1: Canonical IRI | D1: Type | E1: Contact Page | F1: Contact Email | G1: Homepage | H1: Description | I1: Trusted Data Holder | J1: Other Identifiers
A2: STAGE | B2: STAGE | E2: https://stage-healthyageing.eu/contact | F2: sylvain.sebert@oulu.fi | H2: The catalog is maintained and published by the STAGE consortium | I2: true
A3: OULU | B3: OULU | D3: http://publications.europa.eu/resource/authority/corporate-body/EUI | E3: https://oulu.fi | F3: info@oulu.edu.fi | H3: The publisher provides this dataset metadata without warranties of any kind. The publisher shall not be liable for any use of the data beyond the conditions defined by the applicable access and reuse policies. | I3: true
A4: JOHN_DOE | B4: John Doe | D4: john.doe@oulu.fi
A5: JANE_DOE | B5: Jane Doe
